{
  "discovery_summary": {
    "total_endpoints": 0,
    "authenticated_endpoints": 0,
    "public_endpoints": 0,
    "high_risk_endpoints": 0,
    "medium_risk_endpoints": 0,
    "low_risk_endpoints": 0,
    "authentication_types": [],
    "discovery_coverage": 0.0,
    "parameter_coverage": 0.0,
    "discovery_start_time": "2025-08-10T17:45:39.903207",
    "discovery_end_time": null,
    "discovery_duration": null,
    "total_parameters": 0,
    "unique_parameters": 0
  },
  "endpoints": [],
  "authentication_mechanisms": [],
  "api_structure": {
    "base_url": "http://localhost:5000",
    "version": "unknown",
    "title": "VAmPI API (Error)",
    "description": "API structure could not be determined due to error",
    "base_path": null,
    "schemes": [],
    "host": null,
    "port": null,
    "endpoint_groups": {},
    "contact_info": null,
    "license_info": null,
    "external_docs": null,
    "discovered_at": "2025-08-10T17:45:39.903294",
    "discovery_method": "Error"
  },
  "report_id": "vampi_error_20250810_174539",
  "generated_at": "2025-08-10T17:45:39.904427",
  "generator_version": "1.0.0",
  "discovery_config": {},
  "tags": [],
  "notes": "Discovery failed with error: 1 validation error for AuthenticationMechanism\nname\n  Field required [type=missing, input_value={'type': <AuthenticationT...ints_using': ['/users']}, input_type=dict]\n    For further information visit https://errors.pydantic.dev/2.11/v/missing"
}